Workbook

Sheet Main
E2: Shareholders | F2: % Out | H2: Insiders | I2: Shares | J2: % Out | L2: Management | M2: Role | N2: Comment
B3: Last Update | C3: 46001 | E3: usual banks/mms | H3: MICHALEK LIBOR | I3: 1072240 | L3: Mr. Max Roth Levchin | M3: Founder, CEO & Chairman
C4: 0.77152778 | E4: vanguar | H4: LEVCHIN MAX R | I4: 735294 | L4: Mr. Libor Michalek | M4: President & Director
E5: capital reseach | H5: LIEW JEREMY | I5: 312398 | L5: Mr. Robert W. O'Hare | M5: Chief Financial Officer
B6: Price | C6: 68.7 | E6: morgan stanley | H6: JIYANE SIPHELELE | I6: 220968 | L6: Mr. Michael A. Linford | M6: Chief Operating Officer
B7: Shares | C7: =Model!F26 -> 341.02357 | E7: Durable Capital Partners | F7: 0.0217 | L7: Ms. Katherine Adkins Esq. | M7: Chief Legal & Compliance Officer and Secretary
B8: MC | C8: =C6*C7 -> 23428.319 | E8: BAILLIE GIFFORD & CO | F8: 0.0204 | L8: Ms. Siphelele Jiyane | M8: Chief Accounting Officer
B9: CASH | C9: =Model!U41+Model!U45+Model!U43 -> 9476.467 | L9: Mr. Zane Keller C.F.A. | M9: Head of Investor Relations
B10: DEBT | C10: =Model!U60+Model!U61+Model!U62 -> 7736.393 | L10: Ms. Brooke E. Major-Reid | M10: Chief Capital Officer
B11: Net CASH | C11: =C9-C10 -> 1740.074 | L11: Dr. Wayne Pommen Ph.D. | M11: Chief Revenue Officer
B12: EV | C12: =C8-C9+C10 -> 21688.245 | L12: Pat Suh | M12: Senior Vice President of Revenue
B13: PE0 | C13: =C6/Model!F27 -> 399.26241
B14: PE1 | C14: =C6/Model!G27 -> 22.090032
B15: PE2 | C15: =C6/Model!H27 -> 17.937337
B16: EG1 | C16: =Model!G28/Model!F27-1 -> 17.074325
B17: EG2 | C17: =Model!H28/Model!G28-1 -> 0.23151125 | E17: Driving business factors: | L17: Affirm Holdings, Inc. operates payment network in the United States, Canada, and internationally. Its platform includes point-of-sale payment solution for consumers, merchant commerce solutions, and a consumer-focused app. The company's commerce platform, agreements with originating banks, and capital markets partners enables consumers to pay for a purchase over time. It has active merchants covering small businesses, large enterprises, direct-to-consumer brands, brick-and-mortar stores, and companies with an omni-channel presence. The company's merchants represent a range of industries, including sporting goods and outdoors, home and lifestyle, travel and ticketing, electronics, fashion and beauty, equipment and auto, and general merchandise. Affirm Holdings, Inc. was founded in 2012 and is headquartered in San Francisco, California.
B18: PEG1 | C18: =C14/(C16*100) -> 0.012937573 | E18: Affirm earns revenue from merchants when we help them facilitate a transaction and/or direct a consumer to a merchant. These are commonly referred to as our merchant discount rate and affiliate network revenue.
B19: PEG2 | C19: =C15/(C17*100) -> 0.7747933 | E19: Affirm earns interchange fees when consumers use Affirm’s card products over established card networks
B20: RG1 | C20: =Model!G9/Model!F9-1 -> 0.26534738 | E20: We also sell a portion of the assets originated in our platform to third-party investors and recognize a gain or loss on the sale of these loans.
B21: RG2 | C21: =Model!H9/Model!G9-1 -> 0.24019608 | E21: We generate revenue through the simple interest bearing transactions we facilitate
B22: EBIT | C22: =AVERAGE(Model!R20:U20) -> 27.25225 | E22: We make money by providing loan services on behalf of third-party investors that have purchased consumer loans from us.
B23: EBITDA | C23: =AVERAGE(Model!R20:U20) -> 27.25225 | E23: Because we don’t charge any late fees, our success is aligned with consumers successfully managing their finances.
B24: Gross Margin | C24: =AVERAGE(Model!R29:U29) -> 0.47675059
B25: Net Margin | C25: =AVERAGE(Model!R30:U30) -> 0.061232565
B26: EV/EBITDA | C26: =C12/C23 -> 795.83319
B27: Debt to Equity Ratio | C27: =C10/Model!U64 -> 2.3451539 | E27: Notes
B28: Interest Coverage Ratio | E28: Competing with Credit Card Debt
B29: Current Ratio | C29: =Model!U48/Model!U59 -> 22.56584
B30: Quick Ratio | C30: =(Model!U41+Model!U43+Model!U47)/Model!U59 -> 5.6961073
B31: WC over Total Assets
B32: Book Value per Share
B33: Sales to Assets Ratio
B34: Returns on Assets | C34: =SUM(Model!R25:U25)/Model!U48 -> 0.021776206
B35: ROE | C35: =SUM(Model!R25:U25)/Model!U64 -> 0.066031705
B36: FCF Yield

Sheet Model
A1: Main | F1: Year End June 30 | K1: 45016 | L1: 45107 | M1: 45199 | N1: 45291 | O1: 45382 | P1: 45473 | Q1: 45565 | R1: 45657 | S1: 45747 | T1: 45838 | U1: 45930 | V1: 46022 | W1: 46112
C2: FY22 | D2: FY23 | E2: FY24 | F2: FY25 | G2: FY26 | H2: FY27 | K2: Q323 | L2: Q423 | M2: Q124 | N2: Q224 | O2: Q324 | P2: Q424 | Q2: Q125 | R2: Q225 | S2: Q325 | T2: Q425 | U2: Q126 | V2: Q226 | W2: Q326
B3: Merchant network revenue | C3: 458.511 | D3: 507.6 | E3: 674.607 | F3: 882.658 | M3: 145.95 | N3: 188.357 | O3: 159.292 | P3: =E3-O3-N3-M3 -> 181.008 | Q3: 184.339 | R3: 244.895 | S3: 213.973 | T3: =F3-S3-R3-Q3 -> 239.451 | U3: 251.147
B4: Card network revenue | C4: 100.696 | D4: 119.338 | E4: 151.401 | F4: 231.308 | M4: 33.476 | N4: 39.269 | O4: 35.676 | P4: =E4-O4-N4-M4 -> 42.98 | Q4: 47.48 | R4: 58.142 | S4: 58.572 | T4: =F4-S4-R4-Q4 -> 67.114 | U4: 69.33
B5: Total Network Revenue | C5: =SUM(C3:C4) -> 559.207 | D5: =SUM(D3:D4) -> 626.938 | E5: =SUM(E3:E4) -> 826.008 | F5: =SUM(F3:F4) -> 1113.966 | G5: =SUM(G3:G4) -> 0 | H5: =SUM(H3:H4) -> 0 | K5: =SUM(K3:K4) -> 0 | L5: =SUM(L3:L4) -> 0 | M5: =SUM(M3:M4) -> 179.426 | N5: =SUM(N3:N4) -> 227.626 | O5: =SUM(O3:O4) -> 194.968 | P5: =SUM(P3:P4) -> 223.988 | Q5: =SUM(Q3:Q4) -> 231.819 | R5: =SUM(R3:R4) -> 303.037 | ... W5: =SUM(W3:W4) -> 0
B6: Interest Income | C6: 527.88 | D6: 685.217 | E6: 1204.355 | F6: 1608.221 | M6: 262.679 | N6: 288.346 | O6: 315.712 | P6: =E6-O6-N6-M6 -> 337.618 | Q6: 377.064 | R6: 409.367 | S6: 402.701 | T6: =F6-S6-R6-Q6 -> 419.089 | U6: 454.122
B7: Gain on sales of Loans | C7: 196.435 | D7: 188.341 | E7: 197.153 | F7: 381.622 | M7: 34.285 | N7: 52.702 | O7: 40.183 | P7: =E7-O7-N7-M7 -> 69.983 | Q7: 63.613 | R7: 125.287 | S7: 75.838 | T7: =F7-S7-R7-Q7 -> 116.884 | U7: 119.049
B8: Servicing income | C8: 65.77 | D8: 87.489 | E8: 95.483 | F8: 120.602 | M8: 20.157 | N8: 22.436 | O8: 25.294 | P8: =E8-O8-N8-M8 -> 27.596 | Q8: 25.983 | R8: 28.69 | S8: 32.05 | T8: =F8-S8-R8-Q8 -> 33.879 | U8: 39.689
B9: Revenue | C9: =SUM(C5:C8) -> 1349.292 | D9: =SUM(D5:D8) -> 1587.985 | E9: =SUM(E5:E8) -> 2322.999 | F9: =SUM(F5:F8) -> 3224.411 | G9: 4080 | H9: 5060 | K9: =SUM(K5:K8) -> 0 | L9: =SUM(L5:L8) -> 0 | M9: =SUM(M5:M8) -> 496.547 | N9: =SUM(N5:N8) -> 591.11 | O9: =SUM(O5:O8) -> 576.157 | P9: =SUM(P5:P8) -> 659.185 | Q9: =SUM(Q5:Q8) -> 698.479 | R9: =SUM(R5:R8) -> 866.381 | ... U9: =SUM(U5:U8) -> 933.337 | V9: 1060 | W9: 982.57
B10: Rev. Exp. | G10: 4080 | H10: 5060 | V10: 1060 | W10: 982.57
B11: Loss on Loan purchase commitment | C11: 204.081 | D11: 140.265 | E11: 180.395 | F11: 242.264 | M11: 34.866 | N11: 53.63 | O11: 44.143 | P11: =E11-O11-N11-M11 -> 47.756 | Q11: 54.237 | R11: 70.278 | S11: 57.29 | T11: =F11-S11-R11-Q11 -> 60.459 | U11: 71.552
B12: Provision for credit losses | C12: 255.272 | D12: 331.86 | E12: 460.628 | F12: 616.683 | M12: 99.696 | N12: 120.88 | O12: 122.443 | P12: =E12-O12-N12-M12 -> 117.609 | Q12: 159.824 | R12: 152.98 | S12: 147.252 | T12: =F12-S12-R12-Q12 -> 156.627 | U12: 162.752
B13: Funding costs | C13: 69.694 | D13: 183.013 | E13: 344.253 | F13: 425.451 | M13: 73.931 | N13: 84.617 | O13: 90.449 | P13: =E13-O13-N13-M13 -> 95.256 | Q13: 104.145 | R13: 107.762 | S13: 107.631 | T13: =F13-S13-R13-Q13 -> 105.913 | U13: 110.027
B14: Processing and servicing | C14: 157.814 | D14: 257.343 | E14: 343.249 | F14: 457.849 | M14: 75.671 | N14: 90.203 | O14: 88.209 | P14: =E14-O14-N14-M14 -> 89.166 | Q14: 95.146 | R14: 115.96 | S14: 118.398 | T14: =F14-S14-R14-Q14 -> 128.345 | U14: 133.807
B15: COGS | C15: =SUM(C11:C14) -> 686.861 | D15: =SUM(D11:D14) -> 912.481 | E15: =SUM(E11:E14) -> 1328.525 | F15: =SUM(F11:F14) -> 1742.247 | G15: =SUM(G11:G14) -> 0 | H15: =SUM(H11:H14) -> 0 | K15: =SUM(K11:K14) -> 0 | L15: =SUM(L11:L14) -> 0 | M15: =SUM(M11:M14) -> 284.164 | N15: =SUM(N11:N14) -> 349.33 | O15: =SUM(O11:O14) -> 345.244 | P15: =SUM(P11:P14) -> 349.787 | Q15: =SUM(Q11:Q14) -> 413.352 | R15: =SUM(R11:R14) -> 446.98 | ... W15: =SUM(W11:W14) -> 0
B16: Tech and Data analytics | C16: 418.643 | D16: 615.818 | E16: 501.857 | F16: 589.723 | M16: 132.965 | N16: 119.833 | O16: 124.828 | P16: =E16-O16-N16-M16 -> 124.231 | Q16: 134.29 | R16: 148.213 | S16: 152.62 | T16: =F16-S16-R16-Q16 -> 154.6 | U16: 168.106
B17: S&M | C17: 532.343 | D17: 638.28 | E17: 576.405 | F17: 434.847 | M17: 146.866 | N17: 161.265 | O17: 132.95 | P17: =E17-O17-N17-M17 -> 135.324 | Q17: 145.233 | R17: 136.038 | S17: 74.022 | T17: =F17-S17-R17-Q17 -> 79.554 | U17: 78.491
B18: G&A | C18: 577.493 | D18: 586.398 | E18: 525.291 | F18: 545.053 | M18: 140.334 | N18: 132.777 | O18: 128.721 | P18: =E18-O18-N18-M18 -> 123.459 | Q18: 138.482 | R18: 139.412 | S18: 134.303 | T18: =F18-S18-R18-Q18 -> 132.856 | U18: 144.941
B19: Restructuring | C19: 0 | D19: 35.87 | E19: 6.768 | F19: -0.184 | M19: 1.665 | N19: 0.056 | O19: 5.203 | P19: =E19-O19-N19-M19 -> -0.156 | Q19: -0.255 | R19: 0.06 | S19: 0.012 | T19: =F19-S19-R19-Q19 -> -0.001 | U19: 0
B20: Operational Income | C20: =C9-SUM(C15:C19) -> -866.048 | D20: =D9-SUM(D15:D19) -> -1200.862 | E20: =E9-SUM(E15:E19) -> -615.847 | F20: =F9-SUM(F15:F19) -> -87.275 | G20: =G9-SUM(G15:G19) -> 4080 | H20: =H9-SUM(H15:H19) -> 5060 | K20: =K9-SUM(K15:K19) -> 0 | L20: =L9-SUM(L15:L19) -> 0 | M20: =M9-SUM(M15:M19) -> -209.447 | N20: =N9-SUM(N15:N19) -> -172.151 | O20: =O9-SUM(O15:O19) -> -160.789 | P20: =P9-SUM(P15:P19) -> -73.46 | Q20: =Q9-SUM(Q15:Q19) -> -132.623 | R20: =R9-SUM(R15:R19) -> -4.322 | ... W20: =W9-SUM(W15:W19) -> 982.57
B21: Other income | C21: 141.217 | D21: 211.617 | E21: 100.32 | F21: 148.737 | M21: 38.707 | N21: 4.549 | O21: 27.743 | P21: =E21-O21-N21-M21 -> 29.321 | Q21: 34.303 | R21: 87.181 | S21: 13.738 | T21: =F21-S21-R21-Q21 -> 13.515 | U21: 19.358
B22: Net Income before Tax | C22: =C20+SUM(C21:C21) -> -724.831 | D22: =D20+SUM(D21:D21) -> -989.245 | E22: =E20+SUM(E21:E21) -> -515.527 | F22: =F20+SUM(F21:F21) -> 61.462 | G22: =G20+SUM(G21:G21) -> 4080 | H22: =H20+SUM(H21:H21) -> 5060 | K22: =K20+SUM(K21:K21) -> 0 | L22: =L20+SUM(L21:L21) -> 0 | M22: =M20+SUM(M21:M21) -> -170.74 | N22: =N20+SUM(N21:N21) -> -167.602 | O22: =O20+SUM(O21:O21) -> -133.046 | P22: =P20+SUM(P21:P21) -> -44.139 | Q22: =Q20+SUM(Q21:Q21) -> -98.32 | R22: =R20+SUM(R21:R21) -> 82.859 | ... W22: =W20+SUM(W21:W21) -> 982.57
B23: Income Tax | C23: -17.414 | D23: -3.9 | E23: 2.23 | F23: 9.279 | M23: 1.043 | N23: -0.7 | O23: 0.89 | P23: =E23-O23-N23-M23 -> 0.997 | Q23: 1.902 | R23: 2.499 | S23: 2.541 | T23: =F23-S23-R23-Q23 -> 2.337 | U23: 2.326
B24: FX + other | C24: =-5.9-8.022 -> -13.922 | D24: =-8.143-0.822+0.751 -> -8.214 | E24: =-13.655+6.857+0.656 -> -6.142 | F24: =6.025+3.297-2.826 -> 6.496 | M24: =-11.898+1.353+0.763 -> -9.782 | N24: =13.824+4.853-0.614 -> 18.063 | O24: =-10.879-0.03+0.75 -> -10.159 | P24: =E24-O24-N24-M24 -> -4.264 | Q24: =8.346+5.589-1.492 -> 12.443 | R24: =-35.469-2.873-0.089 -> -38.431 | S24: =3.55+0.778-1.279 -> 3.049 | T24: =F24-S24-R24-Q24 -> 29.435 | U24: =-10.003+0.812-0.129 -> -9.32
B25: Net Income | C25: =C22-C23+C24 -> -721.339 | D25: =D22-D23+D24 -> -993.559 | E25: =E22-E23+E24 -> -523.899 | F25: =F22-F23+F24 -> 58.679 | G25: =G22-G23+G24 -> 4080 | H25: =H22-H23+H24 -> 5060 | K25: =K22-K23+K24 -> 0 | L25: =L22-L23+L24 -> 0 | M25: =M22-M23+M24 -> -181.565 | N25: =N22-N23+N24 -> -148.839 | O25: =O22-O23+O24 -> -144.095 | P25: =P22-P23+P24 -> -49.4 | Q25: =Q22-Q23+Q24 -> -87.779 | R25: =R22-R23+R24 -> 41.929 | ... W25: =W22-W23+W24 -> 982.57
B26: Shares (diluted) | C26: 281.70404 | D26: 295.34347 | E26: 309.85713 | F26: 341.02357 | M26: 303.83967 | N26: 307.5716 | O26: 344.22433 | P26: 344.22433 | Q26: 318.23456 | R26: 345.19657 | S26: 312.62673 | T26: 312.62673 | U26: 348.2784
B27: EPS | C27: =C25/C26 -> -2.5606271 | D27: =D25/D26 -> -3.3640798 | E27: =E25/E26 -> -1.690776 | F27: =F25/F26 -> 0.17206729 | G27: 3.11 | H27: 3.83 | K27: =K25/K26 -> #DIV/0! | L27: =L25/L26 -> #DIV/0! | M27: =M25/M26 -> -0.59756845 | N27: =N25/N26 -> -0.48391659 | O27: =O25/O26 -> -0.41860783 | P27: =P25/P26 -> -0.14351106 | Q27: =Q25/Q26 -> -0.27583114 | R27: =R25/R26 -> 0.12146413 | ... U27: =U25/U26 -> 0.20493088 | V27: 0.85 | W27: 0.73
B28: EPS exp. | G28: 3.11 | H28: 3.83 | V28: 0.85 | W28: 0.73
B29: Gross Margin | C29: =1-C15/C9 -> 0.4909471 | D29: =1-D15/D9 -> 0.42538437 | E29: =1-E15/E9 -> 0.42809919 | F29: =1-F15/F9 -> 0.45966969 | G29: =1-G15/G9 -> 1 | H29: =1-H15/H9 -> 1 | K29: =1-K15/K9 -> #DIV/0! | L29: =1-L15/L9 -> #DIV/0! | M29: =1-M15/M9 -> 0.42771983 | N29: =1-N15/N9 -> 0.40902708 | O29: =1-O15/O9 -> 0.40078138 | P29: =1-P15/P9 -> 0.46936444 | Q29: =1-Q15/Q9 -> 0.40821127 | R29: =1-R15/R9 -> 0.48408379 | ... W29: =1-W15/W9 -> 1
B30: Net Margin | C30: =C25/C9 -> -0.53460556 | D30: =D25/D9 -> -0.62567279 | E30: =E25/E9 -> -0.225527 | F30: =F25/F9 -> 0.018198362 | G30: =G25/G9 -> 1 | H30: =H25/H9 -> 1 | K30: =K25/K9 -> #DIV/0! | L30: =L25/L9 -> #DIV/0! | M30: =M25/M9 -> -0.36565521 | N30: =N25/N9 -> -0.25179577 | O30: =O25/O9 -> -0.25009676 | P30: =P25/P9 -> -0.074941026 | Q30: =Q25/Q9 -> -0.12567164 | R30: =R25/R9 -> 0.048395567 | ... W30: =W25/W9 -> 1
B31: Revenue Growth | D31: =D9/C9-1 -> 0.17690241 | E31: =E9/D9-1 -> 0.46285954 | F31: =F9/E9-1 -> 0.38803805 | G31: =G9/F9-1 -> 0.26534738 | H31: =H9/G9-1 -> 0.24019608 | O31: =O9/K9-1 -> #DIV/0! | P31: =P9/L9-1 -> #DIV/0! | Q31: =Q9/M9-1 -> 0.40667248 | R31: =R9/N9-1 -> 0.4656849 | S31: =S9/O9-1 -> 0.35923715 | T31: =T9/P9-1 -> 0.32954633 | U31: =U9/Q9-1 -> 0.33624203 | V31: =V9/R9-1 -> 0.2234802 | W31: =W9/S9-1 -> 0.25466395
B32: Sales & Marketing / REV | C32: =C17/C9 -> 0.39453506 | D32: =D17/D9 -> 0.40194334 | E32: =E17/E9 -> 0.24812968 | F32: =F17/F9 -> 0.13486091 | G32: =G16/G9 -> 0 | H32: =H16/H9 -> 0 | K32: =K17/K9 -> #DIV/0! | L32: =L17/L9 -> #DIV/0! | M32: =M17/M9 -> 0.29577462 | N32: =N17/N9 -> 0.27281724 | O32: =O17/O9 -> 0.23075308 | P32: =P17/P9 -> 0.20528987 | Q32: =Q17/Q9 -> 0.20792751 | R32: =R17/R9 -> 0.15701868 | ... W32: =W17/W9 -> 0
B33: R&D / REV | C33: =C16/C9 -> 0.31026864 | D33: =D16/D9 -> 0.38779837 | E33: =E16/E9 -> 0.21603841 | F33: =F16/F9 -> 0.18289325 | G33: =G16/G9 -> 0 | H33: =H16/H9 -> 0 | K33: =K16/K9 -> #DIV/0! | L33: =L16/L9 -> #DIV/0! | M33: =M16/M9 -> 0.26777928 | N33: =N16/N9 -> 0.20272538 | O33: =O16/O9 -> 0.21665622 | P33: =P16/P9 -> 0.18846151 | Q33: =Q16/Q9 -> 0.19226061 | R33: =R16/R9 -> 0.17107139 | ... W33: =W16/W9 -> 0
B34: G&A / REV | C34: =C19/C9 -> 0 | D34: =D18/D9 -> 0.36927175 | E34: =E18/E9 -> 0.22612623 | F34: =F18/F9 -> 0.16903955 | G34: =G18/G9 -> 0 | H34: =H18/H9 -> 0 | K34: =K18/K9 -> #DIV/0! | L34: =L18/L9 -> #DIV/0! | M34: =M18/M9 -> 0.28261977 | N34: =N18/N9 -> 0.22462317 | O34: =O18/O9 -> 0.22341306 | P34: =P18/P9 -> 0.18729037 | Q34: =Q18/Q9 -> 0.19826222 | R34: =R18/R9 -> 0.16091304 | ... W34: =W18/W9 -> 0
B35: Network Revenue y/y | D35: =D5/C5-1 -> 0.12111973 | E35: =E5/D5-1 -> 0.31752741 | F35: =F5/E5-1 -> 0.34861406 | G35: =G5/F5-1 -> -1 | H35: =H5/G5-1 -> #DIV/0! | K35: =K5/J5-1 -> #DIV/0! | L35: =L5/K5-1 -> #DIV/0! | M35: =M5/L5-1 -> #DIV/0! | N35: =N5/M5-1 -> 0.26863442 | O35: =O5/N5-1 -> -0.14347219 | P35: =P5/O5-1 -> 0.14884494 | Q35: =Q5/P5-1 -> 0.034961694 | R35: =R5/Q5-1 -> 0.30721382 | ... W35: =W5/V5-1 -> #DIV/0!
B36: Interest Income y/y | D36: =D6/C6-1 -> 0.29805448 | E36: =E6/D6-1 -> 0.75762569 | F36: =F6/E6-1 -> 0.335338 | G36: =G6/F6-1 -> -1 | H36: =H6/G6-1 -> #DIV/0! | K36: =K6/J6-1 -> #DIV/0! | L36: =L6/K6-1 -> #DIV/0! | M36: =M6/L6-1 -> #DIV/0! | N36: =N6/M6-1 -> 0.097712417 | O36: =O6/N6-1 -> 0.094906813 | P36: =P6/O6-1 -> 0.069386023 | Q36: =Q6/P6-1 -> 0.11683619 | R36: =R6/Q6-1 -> 0.085669807 | ... W36: =W6/V6-1 -> #DIV/0!
B37: EPS Growth | C37: =C27/#REF!-1 -> #REF! | D37: =D27/C27-1 -> 0.31377187 | E37: =E27/D27-1 -> -0.49740313 | F37: =F27/E27-1 -> -1.1017682 | G37: =G27/F27-1 -> 17.074325 | H37: =H27/G27-1 -> 0.23151125 | O37: =O25/K25-1 -> #DIV/0! | P37: =P25/L25-1 -> #DIV/0! | Q37: =Q25/M25-1 -> -0.51654229 | R37: =R25/N25-1 -> -1.2817071 | S37: =S25/O25-1 -> -1.0406121 | T37: =T25/P25-1 -> -2.9975101 | U37: =U25/Q25-1 -> -1.8130988 | V37: =V25/R25-1 -> 24.280832 | W37: =W25/S25-1 -> 166.90328
B40: Net Cash | C40: =C41+C42 -> 0 | D40: =D41+D43+D45-D60-D61-D62 -> 1125.045 | E40: =E41+E43+E45-E60-E61-E62 -> 1399.578 | F40: =F41+F43+F45-F60-F61-F62 -> 1641.751 | G40: =G41+G43+G45-G60-G61-G62 -> 0 | K40: =K41+K43+K45-K60-K61-K62 -> 0 | L40: =L41+L43+L45-L60-L61-L62 -> 0 | M40: =M41+M43+M45-M60-M61-M62 -> 0 | N40: =N41+N43+N45-N60-N61-N62 -> 0 | O40: =O41+O43+O45-O60-O61-O62 -> 0 | P40: =P41+P43+P45-P60-P61-P62 -> 1399.578 | Q40: =Q41+Q43+Q45-Q60-Q61-Q62 -> 1498.636 | R40: =R41+R43+R45-R60-R61-R62 -> 1356.491 | ... W40: =W41+W43+W45-W60-W61-W62 -> 0
B41: Cash | D41: 892.027 | E41: 1013.106 | F41: 1354.455 | P41: =E41 -> 1013.106 | Q41: 1046.16 | R41: 1200.381 | S41: 1351.148 | T41: =F41 -> 1354.455 | U41: 1428.848
B42: Restricted Cash | D42: 367.917 | E42: 282.293 | F42: 401.968 | P42: =E42 -> 282.293 | Q42: 338.462 | R42: 536.776 | S42: 384.811 | T42: =F42 -> 401.968 | U42: 668.762
...

Sheet Analysts
B1: 45413 | C1: 45444 | D1: 45474 | E1: 45505 | F1: 45536 | G1: 45566 | H1: 45597 | I1: 45627 | J1: 45658 | K1: 45689 | L1: 45717 | M1: 45748 | N1: 45778 | O1: 45809 | P1: 45839 | Q1: 45870 | R1: 45901 | S1: 45931 | T1: 45962 | U1: 45992 | V1: 46023 | W1: 46054
A2: Sell | B2: 6 | C2: 6 | D2: 5 | E2: 6 | F2: 5 | G2: 5 | H2: 2 | I2: 1 | J2: 1 | K2: 1
A3: Hold | B3: 9 | C3: 8 | D3: 9 | E3: 9 | F3: 9 | G3: 9 | H3: 9 | I3: 7 | J3: 6 | K3: 8 | L3: 9 | M3: 8 | N3: 8 | O3: 7 | P3: 8 | Q3: 10 | R3: 11 | S3: 12 | T3: 10 | U3: 11
A4: Buy | B4: 3 | C4: 4 | D4: 5 | E4: 5 | F4: 6 | G4: 7 | H4: 9 | I4: 9 | J4: 10 | K4: 10 | L4: 10 | M4: 12 | N4: 14 | O4: 15 | P4: 17 | Q4: 18 | R4: 18 | S4: 18 | T4: 18 | U4: 18
A5: Strong buy | J5: 1 | K5: 1 | L5: 1 | M5: 1 | N5: 1 | O5: 1 | P5: 1 | Q5: 1 | R5: 1 | S5: 1 | T5: 3 | U5: 3
A8: Price Targets
A9: Actual Price | B9: 32.65 | C9: 30.97 | D9: 32.66 | E9: 32.85 | F9: 37.24 | G9: 43.1 | H9: 46.38 | I9: 67.85 | J9: 62.39 | K9: 64.79 | L9: 70.24 | M9: 43.85 | N9: 48.67 | O9: 65.05 | P9: 65.95 | Q9: 70.86 | R9: 82.97 | S9: 78.71 | T9: 72.59 | U9: 67.77
A10: Consensus Target | B10: 27.86 | C10: 27.53 | D10: 30.1 | E10: 27.15 | F10: 34.32 | G10: 35.53 | H10: 43.08 | I10: 52.53 | J10: 60.94 | K10: 62.88 | L10: 62.41 | M10: 69.76 | N10: 66.74 | O10: 54.49 | P10: 65.67 | Q10: 68.09 | R10: 77.35 | S10: 82.97 | T10: 87.35 | U10: 86.57

Sheet Model-graph
A1: Main

Sheet KPIs

Sheet Catalysts
A1: Main | B1: Date | C1: Close
E2: Date | F2: Event | M2: Earnings
E3: 45328 | F3: xxx
E4: 45302 | F4: xxx

Sheet DoR
A1: Main | B1: Date | C1: Price | D1: w/w | H1: Close to Close Weekly returns
D2: =C2/C3-1 -> #DIV/0!
D3: =C3/C4-1 -> #DIV/0! | H3: Intervals | I3: Bin | J3: Frequency | K3: Range | L3: Probability | M3: Cumulative Percentage
D4: =C4/C5-1 -> #DIV/0! | H4: =$I$19-3*$I$23 -> #DIV/0! | I4: =H4 -> #DIV/0! | J4: =COUNTIF(D:D,"<="&H4) -> 67 | K4: ="Less than "&TEXT(H4,"0,00%") -> #DIV/0! | L4: =J4/$I$31 -> #DIV/0! | M4: =L4 -> #DIV/0!
D5: =C5/C6-1 -> #DIV/0! | H5: =$I$19-2.4*$I$23 -> #DIV/0! | I5: =H5 -> #DIV/0! | J5: =COUNTIFS(D:D,"<="&H5,D:D,">"&H4) -> 67 | K5: =TEXT(H4,"0,00%")&" to "&TEXT(H5,"0,00%") -> #DIV/0! | L5: =J5/$I$31 -> #DIV/0! | M5: =M4+L5 -> #DIV/0!
D6: =C6/C7-1 -> #DIV/0! | H6: =$I$19-1.8*$I$23 -> #DIV/0! | I6: =H6 -> #DIV/0! | J6: =COUNTIFS(D:D,"<="&H6,D:D,">"&H5) -> 67 | K6: =TEXT(H5,"0,00%")&" to "&TEXT(H6,"0,00%") -> #DIV/0! | L6: =J6/$I$31 -> #DIV/0! | M6: =M5+L6 -> #DIV/0!
D7: =C7/C8-1 -> #DIV/0! | H7: =$I$19-1.2*$I$23 -> #DIV/0! | I7: =H7 -> #DIV/0! | J7: =COUNTIFS(D:D,"<="&H7,D:D,">"&H6) -> 67 | K7: =TEXT(H6,"0,00%")&" to "&TEXT(H7,"0,00%") -> #DIV/0! | L7: =J7/$I$31 -> #DIV/0! | M7: =M6+L7 -> #DIV/0!
D8: =C8/C9-1 -> #DIV/0! | H8: =$I$19-0.6*$I$23 -> #DIV/0! | I8: =H8 -> #DIV/0! | J8: =COUNTIFS(D:D,"<="&H8,D:D,">"&H7) -> 67 | K8: =TEXT(H7,"0,00%")&" to "&TEXT(H8,"0,00%") -> #DIV/0! | L8: =J8/$I$31 -> #DIV/0! | M8: =M7+L8 -> #DIV/0!
D9: =C9/C10-1 -> #DIV/0! | H9: =$I$19 -> #DIV/0! | I9: =H9 -> #DIV/0! | J9: =COUNTIFS(D:D,"<="&H9,D:D,">"&H8) -> 67 | K9: =TEXT(H8,"0,00%")&" to "&TEXT(H9,"0,00%") -> #DIV/0! | L9: =J9/$I$31 -> #DIV/0! | M9: =M8+L9 -> #DIV/0!
D10: =C10/C11-1 -> #DIV/0! | H10: =$I$19+0.6*$I$23 -> #DIV/0! | I10: =H10 -> #DIV/0! | J10: =COUNTIFS(D:D,"<="&H10,D:D,">"&H9) -> 67 | K10: =TEXT(H9,"0,00%")&" to "&TEXT(H10,"0,00%") -> #DIV/0! | L10: =J10/$I$31 -> #DIV/0! | M10: =M9+L10 -> #DIV/0!
D11: =C11/C12-1 -> #DIV/0! | H11: =$I$19+1.2*$I$23 -> #DIV/0! | I11: =H11 -> #DIV/0! | J11: =COUNTIFS(D:D,"<="&H11,D:D,">"&H10) -> 67 | K11: =TEXT(H10,"0,00%")&" to "&TEXT(H11,"0,00%") -> #DIV/0! | L11: =J11/$I$31 -> #DIV/0! | M11: =M10+L11 -> #DIV/0!
D12: =C12/C13-1 -> #DIV/0! | H12: =$I$19+1.8*$I$23 -> #DIV/0! | I12: =H12 -> #DIV/0! | J12: =COUNTIFS(D:D,"<="&H12,D:D,">"&H11) -> 67 | K12: =TEXT(H11,"0,00%")&" to "&TEXT(H12,"0,00%") -> #DIV/0! | L12: =J12/$I$31 -> #DIV/0! | M12: =M11+L12 -> #DIV/0!
D13: =C13/C14-1 -> #DIV/0! | H13: =$I$19+2.4*$I$23 -> #DIV/0! | I13: =H13 -> #DIV/0! | J13: =COUNTIFS(D:D,"<="&H13,D:D,">"&H12) -> 67 | K13: =TEXT(H12,"0,00%")&" to "&TEXT(H13,"0,00%") -> #DIV/0! | L13: =J13/$I$31 -> #DIV/0! | M13: =M12+L13 -> #DIV/0!
D14: =C14/C15-1 -> #DIV/0! | H14: =$I$19+3*$I$23 -> #DIV/0! | I14: =H14 -> #DIV/0! | J14: =COUNTIFS(D:D,"<="&H14,D:D,">"&H13) -> 67 | K14: =TEXT(H13,"0,00%")&" to "&TEXT(H14,"0,00%") -> #DIV/0! | L14: =J14/$I$31 -> #DIV/0! | M14: =M13+L14 -> #DIV/0!
D15: =C15/C16-1 -> #DIV/0! | I15: More | J15: =COUNTIF(D:D,">"&H14) -> 67 | K15: ="Greater than "&TEXT(H14,"0,00%") -> #DIV/0! | L15: =J15/$I$31 -> #DIV/0! | M15: =M14+L15 -> #DIV/0!
D16: =C16/C17-1 -> #DIV/0!
D17: =C17/C18-1 -> #DIV/0! | H17: Descriptive Statistics
D18: =C18/C19-1 -> #DIV/0!
D19: =C19/C20-1 -> #DIV/0! | H19: Mean | I19: =AVERAGE(D:D) -> #DIV/0!
D20: =C20/C21-1 -> #DIV/0! | H20: Standard Error | I20: =_xlfn.STDEV.S(D:D)/SQRT(COUNT(D:D)) -> #DIV/0!
D21: =C21/C22-1 -> #DIV/0! | H21: Median | I21: =MEDIAN(D:D) -> #DIV/0!
D22: =C22/C23-1 -> #DIV/0! | H22: Mode | I22: =MODE(D:D) -> #DIV/0!
D23: =C23/C24-1 -> #DIV/0! | H23: Standard Deviation | I23: =_xlfn.STDEV.S(D:D) -> #DIV/0!
D24: =C24/C25-1 -> #DIV/0! | H24: Sample Variance | I24: =_xlfn.VAR.S(D:D) -> #DIV/0!
D25: =C25/C26-1 -> #DIV/0! | H25: Kurtosis | I25: =KURT(D:D) -> #DIV/0!
D26: =C26/C27-1 -> #DIV/0! | H26: Skewness | I26: =SKEW(D:D) -> #DIV/0!
D27: =C27/C28-1 -> #DIV/0! | H27: Range | I27: =I29-I28 -> #DIV/0!
D28: =C28/C29-1 -> #DIV/0! | H28: Minimum | I28: =MIN(D:D) -> #DIV/0!
D29: =C29/C30-1 -> #DIV/0! | H29: Maximum | I29: =MAX(D:D) -> #DIV/0!
D30: =C30/C31-1 -> #DIV/0! | H30: Sum | I30: =SUM(D:D) -> #DIV/0!
D31: =C31/C32-1 -> #DIV/0! | H31: Count | I31: =COUNT(D:D) -> 0
D32: =C32/C33-1 -> #DIV/0!
D33: =C33/C34-1 -> #DIV/0! | I33: Average Returns | J33: Count | K33: Frequency % | L33: Frequency Adjusted Return
D34: =C34/C35-1 -> #DIV/0! | H34: Positive Data Points | I34: =AVERAGEIF(D:D,">0") -> #DIV/0! | J34: =COUNTIF(D:D,">0") -> 0 | K34: =J34/$I$31 -> #DIV/0! | L34: =K34*I34 -> #DIV/0!
D35: =C35/C36-1 -> #DIV/0! | H35: Negative Data Points | I35: =AVERAGEIF(D:D,"<0") -> #DIV/0! | J35: =COUNTIF(D:D,"<0") -> 0 | K35: =J35/$I$31 -> #DIV/0! | L35: =K35*I35 -> #DIV/0!
D36: =C36/C37-1 -> #DIV/0! | H36: Zero | I36: 0 | J36: =COUNTIF(D:D,"0") -> 0 | K36: =J36/$I$31 -> #DIV/0! | L36: =K36*I36 -> #DIV/0!
D37: =C37/C38-1 -> #DIV/0!
D38: =C38/C39-1 -> #DIV/0! | H38: Std Dev | I38: Upper Bound | J38: Lower Bound | K38: Actual Count | L38: Actual % Count | M38: Normal % Count
D39: =C39/C40-1 -> #DIV/0! | H39: 1 | I39: =$I$19+($H39*$I$23) -> #DIV/0! | J39: =$I$19-($H39*$I$23) -> #DIV/0! | K39: =COUNTIFS(D:D,"<"&I39,D:D,">"&J39) -> 67 | L39: =K39/$I$31 -> #DIV/0! | M39: 0.6827
D40: =C40/C41-1 -> #DIV/0! | H40: 2 | I40: =$I$19+($H40*$I$23) -> #DIV/0! | J40: =$I$19-($H40*$I$23) -> #DIV/0! | K40: =COUNTIFS(D:D,"<"&I40,D:D,">"&J40) -> 67 | L40: =K40/$I$31 -> #DIV/0! | M40: 0.9545
...
