Workbook

Sheet Main
B2: MNDY | E2: Shareholders | F2: % Out | H2: Insiders | I2: Shares | J2: % Out | L2: Management | M2: Role | N2: Comment
B3: Last Update | C3: 45971 | E3: Sonnipe Ltd | F3: 8.61% | H3: Roy Mann | I3: 5481.89 | J3: =I3/$C$7 -> 0.11234302 | L3: Eran Zinman | M3: Co-Founder, Co-CEO & Director
C4: 0.60069444 | E4: Price (T.Rowe) Associates Inc | F4: 6.49% | H4: Eran Zinman | I4: 2148.07 | J4: =I4/$C$7 -> 0.044021436 | L4: Roy Mann | M4: Co-Founder, Co-CEO & Director
E5: Franklin Resources, Inc. | F5: 4.54% | H5: Eliran Glazer | I5: 30.055 | J5: =I5/$C$7 -> 0.00061593163 | L5: Eliran Glazer | M5: Chief Financial Officer
B6: Price | C6: 185 | E6: Voya Investment Management LLC | F6: 3.39% | H6: Daniel Lereya | I6: 96.75 | J6: =I6/$C$7 -> 0.0019827445 | L6: Daniel Lereya | M6: Chief Product & Technology Officer
B7: Shares | C7: =Model!P19 -> 48796 | E7: Insight Holdings Group, LLC | F7: 3.35% | H7: Yoni Osherov | I7: 71.695 | J7: =I7/$C$7 -> 0.0014692803 | L7: Yoni Osherov | M7: Chief Revenue Officer
B8: MC | C8: =C6*C7 -> 9027260 | E8: Morgan Stanley | F8: 2.68% | H8: Shiran Nawi | I8: 46.188 | J8: =I8/$C$7 -> 0.000946553 | L8: Ouriel Weisz | M8: Vice President of Operations
B9: CASH | C9: =Model!O37+Model!O38+Model!O39 -> 0 | E9: Blackrock Inc. | F9: 2.32% | H9: Avishai Abrahami | I9: 497.458 | J9: =I9/$C$7 -> 0.010194647 | L9: Ms. Shiran Nawi | M9: Chief People & Legal Officer
B10: DEBT | C10: =Model!O46+Model!O47+Model!#REF! -> #REF! | E10: Whale Rock Capital Management LLC | F10: 2.17% | H10: Aviad Eyal | I10: 247.37 | J10: =I10/$C$7 -> 0.0050694729 | L10: Jamison Powell | M10: GM of North America & Senior VP of Sales
B11: Net CASH | C11: =C9-C10 -> #REF! | E11: Renaissance Technologies, LLC | F11: 2.09% | H11: Jeff Horing | I11: 3.142 | J11: =I11/$C$7 -> 6.4390524e-05
B12: EV | C12: =C8-C9+C10 -> #REF! | E12: 1832 Asset Management L.P. | F12: 1.78% | H12: Ronen Faier | I12: 2.574 | J12: =I12/$C$7 -> 5.2750225e-05
B13: PE0 | C13: =C6/Model!X21 -> -61.913186 | H13: Gili Iohan | I13: 2.574 | J13: =I13/$C$7 -> 5.2750225e-05
B14: EG1
B15: EG2
B16: PE1 | C16: =C6/Model!Y22 -> #DIV/0!
B17: PE2 | C17: =C6/Model!Z22 -> 102.20994 | E17: Driving business factors:

Sheet Model
A1: Main
B2: Q220 | C2: Q320 | D2: Q420 | E2: Q121 | F2: Q221 | G2: Q321 | H2: Q421 | I2: Q122 | J2: Q222 | K2: Q322 | L2: Q422 | M2: Q123 | N2: Q223 | O2: Q323 | P2: Q423 | Q2: Q124 | R2: Q224 | U2: FY19 | V2: FY20 | W2: FY21 | X2: FY22 | Y2: FY23 | Z2: FY24 | AA2: FY25
A3: Revenue | B3: 36460 | C3: 42592 | D3: 50142 | E3: 58972 | F3: 70615 | G3: 83018 | H3: 95545 | I3: 108497 | J3: 123718 | K3: 136893 | L3: 149921 | M3: 162256 | N3: 175679 | O3: 189190 | P3: 202570 | U3: 78089 | V3: 161123 | W3: =SUM(E3:H3) -> 308150 | X3: =SUM(I3:L3) -> 519029 | Y3: =SUM(M3:P3) -> 729695
A4: Rev. Exp. | Q4: 210510 | R4: 225200 | Z4: 935770 | AA4: 1190000
A5: COGS | B5: 4883 | C5: 6333 | D5: 6681 | E5: 7924 | F5: 9108 | G5: 10213 | H5: 11768 | I5: 14609 | J5: 16730 | K5: 17830 | L5: 17359 | M5: 17014 | N5: 19516 | O5: 21707 | P5: 22408 | U5: 11978 | V5: 22488 | W5: =SUM(E5:H5) -> 39013 | X5: =SUM(I5:L5) -> 66528 | Y5: =SUM(M5:P5) -> 80645
A6: R&D | B6: 12781 | C6: 12620 | D6: 11428 | E6: 15581 | F6: 16271 | G6: 19875 | H6: 21959 | I6: 26541 | J6: 33962 | K6: 33984 | L6: 32560 | M6: 37063 | N6: 39106 | O6: 38433 | P6: 41898 | U6: 24637 | V6: 43480 | W6: =SUM(E6:H6) -> 73686 | X6: =SUM(I6:L6) -> 127047 | Y6: =SUM(M6:P6) -> 156500
A7: Sales & Marketing | B7: 39636 | C7: 57871 | D7: 56901 | E7: 63048 | F7: 61057 | G7: 67443 | H7: 76535 | I7: 115973 | J7: 96740 | K7: 90970 | L7: 88385 | M7: 107680 | N7: 107443 | O7: 108360 | P7: 114919 | U7: 118534 | V7: 191353 | W7: =SUM(E7:H7) -> 268083 | X7: =SUM(I7:L7) -> 392068 | Y7: =SUM(M7:P7) -> 438402
A8: G&A | B8: 7351 | C8: 6415 | D8: 36828 | E8: 10266 | F8: 11648 | G8: 14698 | H8: 16881 | I8: 18870 | J8: 22466 | K8: 22348 | L8: 21717 | M8: 23251 | N8: 21781 | O8: 23211 | P8: 24490 | U8: 15458 | V8: 54339 | W8: =SUM(E8:H8) -> 53493 | X8: =SUM(I8:L8) -> 85401 | Y8: =SUM(M8:P8) -> 92733
A9: Operational Income | B9: =B3-B5-B6-B7-B8 -> -28191 | C9: =C3-C5-C6-C7-C8 -> -40647 | D9: =D3-D5-D6-D7-D8 -> -61696 | E9: =E3-E5-E6-E7-E8 -> -37847 | F9: =F3-F5-F6-F7-F8 -> -27469 | G9: =G3-G5-G6-G7-G8 -> -29211 | H9: =H3-H5-H6-H7-H8 -> -31598 | I9: =I3-I5-I6-I7-I8 -> -67496 | ... P9: =P3-P5-P6-P7-P8 -> -1145 | U9: =U3-U5-U6-U7-U8 -> -92518 | V9: =V3-V5-V6-V7-V8 -> -150537 | W9: =W3-W5-W6-W7-W8 -> -126125 | X9: =X3-X5-X6-X7-X8 -> -152015 | Y9: =Y3-Y5-Y6-Y7-Y8 -> -38585
A10: Non-GAAP OpInc | U10: =U9+U16 -> -70679 | V10: =V9+V16 -> -86192 | W10: =W9+W16 -> -52596 | X10: =X9+X16 -> -47095 | Y10: =Y9+Y16 -> 61601
A11: Financial Income/Exp | B11: 141 | C11: 239 | D11: -203 | E11: -406 | F11: -359 | G11: -220 | H11: 147 | I11: 1993 | J11: 2452 | K11: 6972 | L11: 11137 | M11: 9883 | N11: 7612 | O11: 11555 | P11: 12861 | U11: 1590 | V11: 526 | W11: =SUM(E11:H11) -> -838 | X11: =SUM(I11:L11) -> 22554 | Y11: =SUM(M11:P11) -> 41911
A12: EBITDA | B12: =B9+B11 -> -28050 | C12: =C9+C11 -> -40408 | D12: =D9+D11 -> -61899 | E12: =E9+E11 -> -38253 | F12: =F9+F11 -> -27828 | G12: =G9+G11 -> -29431 | H12: =H9+H11 -> -31451 | I12: =I9+I11 -> -65503 | ... P12: =P9+P11 -> 11716 | U12: =U9+U11 -> -90928 | V12: =V9+V11 -> -150011 | W12: =W9+W11 -> -126963 | X12: =X9+X11 -> -129461 | Y12: =Y9+Y11 -> 3326
A13: Income Tax | B13: -350 | C13: -671 | D13: -962 | E13: -699 | F13: -1063 | G13: 585 | H13: -1154 | I13: -1175 | J13: -1943 | K13: -1763 | L13: -2525 | M13: -1798 | N13: -2480 | O13: -1546 | P13: 621 | U13: -683 | V13: -2192 | W13: -2331 | X13: -7406 | Y13: -5203
A14: Dividends | B14: -4665 | C14: -4717 | D14: -4717 | E14: -4614 | F14: -3589 | X14: =SUM(I14:L14) -> 0 | Y14: =SUM(M14:P14) -> 0
A15: Net Income | B15: =B12+B13+B14 -> -33065 | C15: =C12+C13+C14 -> -45796 | D15: =D12+D13+D14 -> -67578 | E15: =E12+E13+E14 -> -43566 | F15: =F12+F13+F14 -> -32480 | G15: =G12+G13+G14 -> -28846 | H15: =H12+H13+H14 -> -32605 | I15: =I12+I13+I14 -> -66678 | ... Q15: =Q12+Q13+Q14 -> 0 | U15: =U12+U14+U13 -> -91611 | V15: =V12+V14+V13 -> -152203 | W15: =W12+W14+W13 -> -129294 | X15: =X12+X14+X13 -> -136867 | Y15: =Y12+Y14+Y13 -> -1877 | Z15: =Z12+Z14 -> 0
A16: Share-based comp | F16: 17558 | U16: 21839 | V16: 64345 | W16: 73529 | X16: 104920 | Y16: 100186
A17: Other | X17: =SUM(I17:L17) -> 0 | Y17: =SUM(M17:P17) -> 0
A18: adj. EBITDA | B18: =B16+B17 -> 0 | C18: =C16+C17 -> 0 | D18: =D16+D17 -> 0 | E18: =E16+E17 -> 0 | F18: =F12++F13+F16+F17 -> -11333 | G18: =G16+G17 -> 0 | H18: =H16+H17 -> 0 | I18: =I16+I17 -> 0 | J18: =J16+J17 -> 0 | K18: =K16+K17 -> 0 | L18: =L16+L17 -> 0 | M18: =M16+M17 -> 0 | N18: =N16+N17 -> 0 | ... P18: =P16+P17 -> 0 | U18: =U10+U11+U13 -> -69772 | V18: =V10+V11+V13 -> -87858 | W18: =W10+W11+W13 -> -55765 | X18: =X10+X11+X13 -> -31947 | Y18: =Y10+Y11+Y13 -> 98309
A19: Shares | B19: 11836 | C19: 12240 | D19: 12334 | E19: 12392 | F19: 19417 | G19: 44267 | H19: 44741 | I19: 44978 | J19: 45074 | K19: 45477 | L19: 47659 | M19: 47912 | N19: 48209 | O19: 48536 | P19: 48796 | W19: 30332.006 | X19: 45804.714 | Y19: 48366.378
A20: Non-GAAP Shares
A21: EPS | B21: =B15/B19 -> -2.7935958 | C21: =C15/C19 -> -3.7415033 | D21: =D15/D19 -> -5.4790011 | E21: =E15/E19 -> -3.5156553 | F21: =F15/F19 -> -1.672761 | G21: =G15/G19 -> -0.65163666 | H21: =H15/H19 -> -0.72874992 | I21: =I15/I19 -> -1.4824581 | ... P21: =P15/P19 -> 0.2528281 | V21: =V15/V19 -> #DIV/0! | W21: =W15/W19 -> -4.2626261 | X21: =X15/X19 -> -2.9880549 | Y21: =Y15/Y19 -> -0.03880795
A22: EPS exp. | Q22: 0.4 | R22: 0.48 | Z22: 1.81 | AA22: 2.01
A23: Non-GAAP EPS | B23: =B18/B19 -> 0 | C23: =C18/C19 -> 0 | D23: =D18/D19 -> 0 | E23: =E18/E19 -> 0 | F23: =F18/F19 -> -0.5836638 | G23: =G18/G19 -> 0 | H23: =H18/H19 -> 0 | I23: =I18/I19 -> 0 | ... P23: =P18/P19 -> 0 | W23: =W18/W19 -> -1.838487 | X23: =X18/X19 -> -0.69746096 | Y23: =Y18/Y19 -> 2.0325897
A25: Gross Margin | B25: =1-B5/B3 -> 0.86607241 | C25: =1-C5/C3 -> 0.85131011 | D25: =1-D5/D3 -> 0.86675841 | E25: =1-E5/E3 -> 0.86563115 | F25: =1-F5/F3 -> 0.87101891 | G25: =1-G5/G3 -> 0.87697849 | H25: =1-H5/H3 -> 0.87683291 | I25: =1-I5/I3 -> 0.86535112 | ... P25: =1-P5/P3 -> 0.88938145 | V25: =1-V5/V3 -> 0.86042961 | W25: =1-W5/W3 -> 0.87339607 | X25: =1-X5/X3 -> 0.87182219 | Y25: =1-Y5/Y3 -> 0.88948122
A26: Net Margin | B26: =B15/B3 -> -0.90688426 | C26: =C15/C3 -> -1.0752254 | D26: =D15/D3 -> -1.3477324 | E26: =E15/E3 -> -0.73875738 | F26: =F15/F3 -> -0.45995893 | G26: =G15/G3 -> -0.34746681 | H26: =H15/H3 -> -0.34125281 | I26: =I15/I3 -> -0.61456077 | ... P26: =P15/P3 -> 0.060902404 | V26: =V15/V3 -> -0.94463857 | W26: =W15/W3 -> -0.41958137 | X26: =X15/X3 -> -0.26369817 | Y26: =Y15/Y3 -> -0.0025723076
A27: Revenue y/y | F27: =F3/B3-1 -> 0.93678003 | G27: =G3/C3-1 -> 0.94914538 | H27: =H3/D3-1 -> 0.90548841 | I27: =I3/E3-1 -> 0.83980533 | J27: =J3/F3-1 -> 0.75200736 | K27: =K3/G3-1 -> 0.64895565 | L27: =L3/H3-1 -> 0.56911403 | M27: =M3/I3-1 -> 0.49548835 | ... P27: =P3/L3-1 -> 0.35117829 | Q27: =Q4/M3-1 -> 0.29739424 | R27: =R4/N3-1 -> 0.28188344 | V27: =V3/U3-1 -> 1.0633252 | W27: =W3/V3-1 -> 0.91251404 | X27: =X3/W3-1 -> 0.6843388 | Y27: =Y3/X3-1 -> 0.40588483 | Z27: =Z4/Y3-1 -> 0.28241251 | AA27: =AA4/Z4-1 -> 0.27168001
A28: Sales & Marketing y/y | F28: =F7/F3 -> 0.86464632 | G28: =G7/G3 -> 0.81239008 | H28: =H7/H3 -> 0.80103616 | I28: =I7/I3 -> 1.0689051 | J28: =J7/J3 -> 0.78193957 | K28: =K7/K3 -> 0.66453361 | L28: =L7/L3 -> 0.58954383 | M28: =M7/M3 -> 0.66364264 | ... P28: =P7/P3 -> 0.56730513
A29: adj. EBITDA Margin | B29: =B18/B3 -> 0 | C29: =C18/C3 -> 0 | D29: =D18/D3 -> 0 | E29: =E18/E3 -> 0 | F29: =F18/F3 -> -0.16048998 | G29: =G18/G3 -> 0 | H29: =H18/H3 -> 0 | I29: =I18/I3 -> 0 | ... P29: =P18/P3 -> 0 | W29: =W18/W3 -> -0.18096706 | X29: =X18/X3 -> -0.061551474 | Y29: =Y18/Y3 -> 0.13472615
A30: Net Income y/y | F30: =F15/B15-1 -> -0.017692424 | G30: =G15/C15-1 -> -0.37011966 | H30: =H15/D15-1 -> -0.51752049 | I30: =I15/E15-1 -> 0.53050544 | J30: =J15/F15-1 -> 0.40612685 | K30: =K15/G15-1 -> -0.20162241 | L30: =L15/H15-1 -> -0.95436283 | M30: =M15/I15-1 -> -0.78003239 | ... P30: =P15/L15-1 -> -9.2909946 | Q30: =Q22/M21-1 -> -2.3066612 | R30: =R22/N21-1 -> -4.2893134 | W30: =-(W15/V15-1) -> 0.15051609 | X30: =-(X15/W15-1) -> -0.058571937 | Y30: =-(Y15/X15-1) -> 0.98628596 | Z30: =Z22/Y21-1 -> -47.639928 | AA30: =AA22/Z22-1 -> 0.11049724
A31: R&D part of Rev | W31: =W6/W3 -> 0.2391238 | X31: =X6/X3 -> 0.24477823 | Y31: =Y6/Y3 -> 0.21447317
A32: S&M part of Rev | W32: =W7/W3 -> 0.86997566 | X32: =X7/X3 -> 0.75538746 | Y32: =Y7/Y3 -> 0.6008017
A33: G&A part of Rev | W33: =W8/W3 -> 0.17359403 | X33: =X8/X3 -> 0.16453994 | Y33: =Y8/Y3 -> 0.1270846
A36: Net Cash | B36: =B37 -> 0 | C36: =C37 -> 0 | D36: =D37 -> 0 | E36: =E37 -> 0 | F36: =F37 -> 0 | G36: =G37 -> 0 | H36: =H37 -> 0 | I36: =I37 -> 0 | ... P36: =P37 -> 0 | V36: =V37 -> 139814 | W36: =W37 -> 886812 | X36: =X37 -> 885894 | Y36: =Y37 -> 1116128
A37: Cash | V37: =129814+10000 -> 139814 | W37: 886812 | X37: 885894 | Y37: 1116128
A38: AR | V38: 3911 | W38: 8509 | X38: 13226 | Y38: 17911
A39: Prepaid Expense + other | V39: 3898 | W39: 18172 | X39: 24725 | Y39: 39103
A40: Current Assets | B40: =SUM(B37:B39) -> 0 | C40: =SUM(C37:C39) -> 0 | D40: =SUM(D37:D39) -> 0 | E40: =SUM(E37:E39) -> 0 | F40: =SUM(F37:F39) -> 0 | G40: =SUM(G37:G39) -> 0 | H40: =SUM(H37:H39) -> 0 | I40: =SUM(I37:I39) -> 0 | ... O40: =SUM(O37:O39) -> 0 | V40: =SUM(V37:V39) -> 147623 | W40: =SUM(W37:W39) -> 913493 | X40: =SUM(X37:X39) -> 923845 | Y40: =SUM(Y37:Y39) -> 1173142
A41: PP&E | V41: 7178 | W41: 19599 | X41: 34416 | Y41: 37418
A42: Right-of-use Asset | V42: =D42 -> 0 | W42: =H42 -> 0 | X42: 80197 | Y42: 62280
A43: Operating Lease | V43: =D43 -> 0 | W43: =H43 -> 0
...

Sheet Model-graph

Sheet KPI
B1: 2019 | C1: 2020 | D1: 2021 | E1: 2022 | F1: 2023
A2: USA | B2: 36439 | C2: 77933 | D2: 148291 | E2: 255495 | F2: 364070
A3: EMEA | B3: 24809 | C3: 49747 | D3: 67121 | E3: 111854 | F3: 157134
A4: UK | D4: 30171 | E4: 50625 | F4: 73236
A5: RoW | B5: 16841 | C5: 33443 | D5: 62567 | E5: 101055 | F5: 135255
B6: =SUM(B2:B5) -> 78089 | C6: =SUM(C2:C5) -> 161123 | D6: =SUM(D2:D5) -> 308150 | E6: =SUM(E2:E5) -> 519029 | F6: =SUM(F2:F5) -> 729695
A10: ARR | D10: 793 | E10: 1474 | F10: 2295
A11: Customer Growth | E11: =E10/D10-1 -> 0.85876419 | F11: =F10/E10-1 -> 0.55698779

Sheet Catalysts
A1: Date | B1: Close
A2: 44354 | B2: 189.31 | D2: Date | E2: Event | L2: Earnings
A3: 44361 | B3: 232.51 | D3: 45328 | E3: xxx
A4: 44368 | B4: 232.36999 | D4: 45302 | E4: xxx
A5: 44375 | B5: 229.23
A6: 44382 | B6: 232.03999
A7: 44389 | B7: 198.98
A8: 44396 | B8: 204.92999
A9: 44403 | B9: 221.28999
A10: 44410 | B10: 226
A11: 44417 | B11: 267.89999
A12: 44424 | B12: 352.28
A13: 44431 | B13: 357.19
A14: 44438 | B14: 379.81
A15: 44445 | B15: 371.97
A16: 44452 | B16: 374.14999
... A150: 45390 | B150: 215.75

Sheet DoR
A1: Main | B1: Date | C1: Price | D1: w/w | H1: Close to Close Weekly returns
B2: 45404 | C2: 187.25 | D2: =C2/C3-1 -> 0.05155276
B3: 45397 | C3: 178.07 | D3: =C3/C4-1 -> -0.077883072 | H3: Intervals | I3: Bin | J3: Frequency | K3: Range | L3: Probability | M3: Cumulative Percentage
B4: 45390 | C4: 193.11 | D4: =C4/C5-1 -> -0.11009217 | H4: =$I$19-3*$I$23 -> -0.29929356 | I4: =H4 -> -0.29929356 | J4: =COUNTIF(D:D,"<="&H4) -> 0 | K4: ="Less than "&TEXT(H4,"0,00%") -> Less than -29,93% | L4: =J4/$I$31 -> 0 | M4: =L4 -> 0
B5: 45383 | C5: 217 | D5: =C5/C6-1 -> -0.039270355 | H5: =$I$19-2.4*$I$23 -> -0.23845054 | I5: =H5 -> -0.23845054 | J5: =COUNTIFS(D:D,"<="&H5,D:D,">"&H4) -> 1 | K5: =TEXT(H4,"0,00%")&" to "&TEXT(H5,"0,00%") -> -29,93% to -23,85% | L5: =J5/$I$31 -> 0.0066666667 | M5: =M4+L5 -> 0.0066666667
B6: 45376 | C6: 225.86999 | D6: =C6/C7-1 -> -0.0093421272 | H6: =$I$19-1.8*$I$23 -> -0.17760753 | I6: =H6 -> -0.17760753 | J6: =COUNTIFS(D:D,"<="&H6,D:D,">"&H5) -> 4 | K6: =TEXT(H5,"0,00%")&" to "&TEXT(H6,"0,00%") -> -23,85% to -17,76% | L6: =J6/$I$31 -> 0.026666667 | M6: =M5+L6 -> 0.033333333
B7: 45369 | C7: 228 | D7: =C7/C8-1 -> 0.050691244 | H7: =$I$19-1.2*$I$23 -> -0.11676452 | I7: =H7 -> -0.11676452 | J7: =COUNTIFS(D:D,"<="&H7,D:D,">"&H6) -> 9 | K7: =TEXT(H6,"0,00%")&" to "&TEXT(H7,"0,00%") -> -17,76% to -11,68% | L7: =J7/$I$31 -> 0.06 | M7: =M6+L7 -> 0.093333333
B8: 45362 | C8: 217 | D8: =C8/C9-1 -> -0.015649794 | H8: =$I$19-0.6*$I$23 -> -0.055921505 | I8: =H8 -> -0.055921505 | J8: =COUNTIFS(D:D,"<="&H8,D:D,">"&H7) -> 24 | K8: =TEXT(H7,"0,00%")&" to "&TEXT(H8,"0,00%") -> -11,68% to -5,59% | L8: =J8/$I$31 -> 0.16 | M8: =M7+L8 -> 0.25333333
B9: 45355 | C9: 220.45 | D9: =C9/C10-1 -> -0.03699983 | H9: =$I$19 -> 0.0049215075 | I9: =H9 -> 0.0049215075 | J9: =COUNTIFS(D:D,"<="&H9,D:D,">"&H8) -> 37 | K9: =TEXT(H8,"0,00%")&" to "&TEXT(H9,"0,00%") -> -5,59% to 0,49% | L9: =J9/$I$31 -> 0.24666667 | M9: =M8+L9 -> 0.5
B10: 45348 | C10: 228.92 | D10: =C10/C11-1 -> 0.10110632 | H10: =$I$19+0.6*$I$23 -> 0.06576452 | I10: =H10 -> 0.06576452 | J10: =COUNTIFS(D:D,"<="&H10,D:D,">"&H9) -> 42 | K10: =TEXT(H9,"0,00%")&" to "&TEXT(H10,"0,00%") -> 0,49% to 6,58% | L10: =J10/$I$31 -> 0.28 | M10: =M9+L10 -> 0.78
B11: 45341 | C11: 207.89999 | D11: =C11/C12-1 -> -0.077230398 | H11: =$I$19+1.2*$I$23 -> 0.12660753 | I11: =H11 -> 0.12660753 | J11: =COUNTIFS(D:D,"<="&H11,D:D,">"&H10) -> 19 | K11: =TEXT(H10,"0,00%")&" to "&TEXT(H11,"0,00%") -> 6,58% to 12,66% | L11: =J11/$I$31 -> 0.12666667 | M11: =M10+L11 -> 0.90666667
B12: 45334 | C12: 225.3 | D12: =C12/C13-1 -> -0.045015239 | H12: =$I$19+1.8*$I$23 -> 0.18745055 | I12: =H12 -> 0.18745055 | J12: =COUNTIFS(D:D,"<="&H12,D:D,">"&H11) -> 8 | K12: =TEXT(H11,"0,00%")&" to "&TEXT(H12,"0,00%") -> 12,66% to 18,75% | L12: =J12/$I$31 -> 0.053333333 | M12: =M11+L12 -> 0.96
B13: 45327 | C13: 235.92 | D13: =C13/C14-1 -> 0.1021209 | H13: =$I$19+2.4*$I$23 -> 0.24829356 | I13: =H13 -> 0.24829356 | J13: =COUNTIFS(D:D,"<="&H13,D:D,">"&H12) -> 3 | K13: =TEXT(H12,"0,00%")&" to "&TEXT(H13,"0,00%") -> 18,75% to 24,83% | L13: =J13/$I$31 -> 0.02 | M13: =M12+L13 -> 0.98
B14: 45320 | C14: 214.06 | D14: =C14/C15-1 -> 0.026026903 | H14: =$I$19+3*$I$23 -> 0.30913657 | I14: =H14 -> 0.30913657 | J14: =COUNTIFS(D:D,"<="&H14,D:D,">"&H13) -> 1 | K14: =TEXT(H13,"0,00%")&" to "&TEXT(H14,"0,00%") -> 24,83% to 30,91% | L14: =J14/$I$31 -> 0.0066666667 | M14: =M13+L14 -> 0.98666667
B15: 45313 | C15: 208.63001 | D15: =C15/C16-1 -> 0.066451974 | I15: More | J15: =COUNTIF(D:D,">"&H14) -> 2 | K15: ="Greater than "&TEXT(H14,"0,00%") -> Greater than 30,91% | L15: =J15/$I$31 -> 0.013333333 | M15: =M14+L15 -> 1
B16: 45306 | C16: 195.63001 | D16: =C16/C17-1 -> 0.025798321
B17: 45299 | C17: 190.71001 | D17: =C17/C18-1 -> 0.078737567 | H17: Descriptive Statistics
B18: 45292 | C18: 176.78999 | D18: =C18/C19-1 -> -0.058676349
B19: 45285 | C19: 187.81 | D19: =C19/C20-1 -> -0.0087090095 | H19: Mean | I19: =AVERAGE(D:D) -> 0.0049215075
B20: 45278 | C20: 189.46001 | D20: =C20/C21-1 -> 0.002062728 | H20: Standard Error | I20: =_xlfn.STDEV.S(D:D)/SQRT(COUNT(D:D)) -> 0.0082796853
B21: 45271 | C21: 189.07001 | D21: =C21/C22-1 -> 0.080214866 | H21: Median | I21: =MEDIAN(D:D) -> 0.0046071114
B22: 45264 | C22: 175.03 | D22: =C22/C23-1 -> -0.0075976415 | H22: Mode | I22: =MODE(D:D) -> #N/A
B23: 45257 | C23: 176.36999 | D23: =C23/C24-1 -> 0.0075406568 | H23: Standard Deviation | I23: =_xlfn.STDEV.S(D:D) -> 0.10140502
B24: 45250 | C24: 175.05 | D24: =C24/C25-1 -> 0.031526259 | H24: Sample Variance | I24: =_xlfn.VAR.S(D:D) -> 0.010282978
B25: 45243 | C25: 169.7 | D25: =C25/C26-1 -> 0.21110479 | H25: Kurtosis | I25: =KURT(D:D) -> 1.5661201
B26: 45236 | C26: 140.11999 | D26: =C26/C27-1 -> 0.061836826 | H26: Skewness | I26: =SKEW(D:D) -> 0.53352626
B27: 45229 | C27: 131.96001 | D27: =C27/C28-1 -> 0.02104613 | H27: Range | I27: =I29-I28 -> 0.64261674
B28: 45222 | C28: 129.24 | D28: =C28/C29-1 -> -0.020983184 | H28: Minimum | I28: =MIN(D:D) -> -0.24576271
B29: 45215 | C29: 132.01 | D29: =C29/C30-1 -> -0.057609986 | H29: Maximum | I29: =MAX(D:D) -> 0.39685403
B30: 45208 | C30: 140.08 | D30: =C30/C31-1 -> -0.11688308 | H30: Sum | I30: =SUM(D:D) -> 0.73822613
B31: 45201 | C31: 158.61999 | D31: =C31/C32-1 -> -0.0037684085 | H31: Count | I31: =COUNT(D:D) -> 150
B32: 45194 | C32: 159.22 | D32: =C32/C33-1 -> 0.014140134
B33: 45187 | C33: 157 | D33: =C33/C34-1 -> -0.039050097 | I33: Average Returns | J33: Count | K33: Frequency % | L33: Frequency Adjusted Return
B34: 45180 | C34: 163.38001 | D34: =C34/C35-1 -> -0.045677524 | H34: Positive Data Points | I34: =AVERAGEIF(D:D,">0") -> 0.075259194 | J34: =COUNTIF(D:D,">0") -> 79 | K34: =J34/$I$31 -> 0.52666667 | L34: =K34*I34 -> 0.039636509
B35: 45173 | C35: 171.2 | D35: =C35/C36-1 -> -0.030522675 | H35: Negative Data Points | I35: =AVERAGEIF(D:D,"<0") -> -0.073341553 | J35: =COUNTIF(D:D,"<0") -> 71 | K35: =J35/$I$31 -> 0.47333333 | L35: =K35*I35 -> -0.034715002
B36: 45166 | C36: 176.59 | D36: =C36/C37-1 -> 0.043737774 | H36: Zero | I36: 0 | J36: =COUNTIF(D:D,"0") -> 0 | K36: =J36/$I$31 -> 0 | L36: =K36*I36 -> 0
B37: 45159 | C37: 169.19 | D37: =C37/C38-1 -> 0.050412831
B38: 45152 | C38: 161.07001 | D38: =C38/C39-1 -> 0.033560133 | H38: Std Dev | I38: Upper Bound | J38: Lower Bound | K38: Actual Count | L38: Actual % Count | M38: Normal % Count
B39: 45145 | C39: 155.84 | D39: =C39/C40-1 -> -0.031989619 | H39: 1 | I39: =$I$19+($H39*$I$23) -> 0.10632653 | J39: =$I$19-($H39*$I$23) -> -0.096483513 | K39: =COUNTIFS(D:D,"<"&I39,D:D,">"&J39) -> 110 | L39: =K39/$I$31 -> 0.73333333 | M39: 0.6827
B40: 45138 | C40: 160.99 | D40: =C40/C41-1 -> -0.10176863 | H40: 2 | I40: =$I$19+($H40*$I$23) -> 0.20773155 | J40: =$I$19-($H40*$I$23) -> -0.19788853 | K40: =COUNTIFS(D:D,"<"&I40,D:D,">"&J40) -> 141 | L40: =K40/$I$31 -> 0.94 | M40: 0.9545
...
