Workbook

Sheet Main
E2: Shareholders | F2: % Out | H2: Insiders | I2: Shares | J2: % Out | L2: Management | M2: Role | N2: Comment
B3: Last Update | C3: 46006 | E3: General Catalyst Group Management, LLC | F3: 0.0878 | H3: 4.21% % of Shares Held by All Insider | L3: Mr. Jeremy D. Allaire | M3: Co-Founder, Chairman & CEO
C4: 0.78888889 | E4: FMR, LLC | F4: 0.0599 | L4: Mr. Heath P. Tarbert | M4: President & Chief Legal Officer
E5: IDG China Capital Fund III Associates L.P. | F5: 0.0509 | L5: Mr. Jeremy Fox-Geen | M5: Chief Financial Officer
B6: Price | C6: 76.04 | E6: Marshall Wace LLP | F6: 0.0372 | L6: Mr. Nikhil Chandhok | M6: Chief Product & Technology Officer
B7: Shares | C7: =Model!P21 -> 107.514 | L7: Ms. Elisabeth Bentel Carpenter | M7: Chief Strategic Engagement Officer
B8: MC | C8: =C6*C7 -> 8175.3646 | L8: Mr. John Andrews | M8: Vice President of Capital Markets & Investor Relations
B9: CASH | C9: =Model!Q37 -> 1348.901 | L9: Mr. Mandeep Walia | M9: Chief Compliance & Risk Officer
B10: DEBT | C10: =Model!Q55+Model!Q58 -> 149.094 | L10: Mr. Tim Queenan | M10: Senior Vice President of Marketing
B11: Net CASH | C11: =C9-C10 -> 1199.807 | L11: Mr. Brian Christman | M11: Chief People Officer
B12: EV | C12: =C8-C9+C10 -> 6975.5576 | L12: Ms. Li Fan | M12: Chief Technology & AI Officer
B13: PE0 | C13: =C6/Model!E22 -> #DIV/0!
B14: PE1 | C14: =C6/Model!F23 -> -53.929078
B15: PE2 | C15: =C6/Model!G23 -> 65.551724
B16: EG1 | C16: 0
B17: EG2 | C17: 1 | E17: Driving business factors: | L17: Circle Internet Group, Inc. operates as a platform, network, and market infrastructure for stablecoin and blockchain applications. The company provides a suite of stablecoins and related products that include a network utility and application platform for organizations to benefit from stablecoins and the internet financial system; and issues a U.S. dollar-denominated stablecoin. Its stablecoins network comprises circle stablecoins, tokenized funds, liquidity, payments, and developer services, as well as integration services. The company was founded in 2013 and is based in New York, New York.
B18: PEG1 | C18: =C14/(C16*100) -> #DIV/0!
B19: PEG2 | C19: =C15/(C17*100) -> 0.65551724
B20: RG1 | C20: =Model!D4/Model!C3-1 -> #DIV/0!
B21: RG2 | C21: =Model!G6/Model!F6-1 -> 0.21978022
B22: EBIT
B23: EBITDA | C23: =Model!C10 -> 0
B24: Gross Margin | C24: =Model!C17 -> 0
B25: Net Margin
B26: EV/EBITDA | C26: =C12/C23 -> #DIV/0!
B27: Debt to Equity Ratio | E27: Notes
B28: Interest Coverage Ratio
B29: Current Ratio
B30: Quick Ratio
B31: WC over Total Assets
B32: Book Value per Share
B33: Sales to Assets Ratio
B34: Returns on Assets
B35: ROE
B36: FCF Yield

Sheet Model
A1: Main
C2: FY22 | D2: FY23 | E2: FY24 | F2: FY25 | G2: FY26 | K2: Q124 | L2: Q224 | M2: Q324 | N2: Q424 | O2: Q125 | P2: Q225 | Q2: Q325 | R2: Q425 | S2: Q126 | T2: Q226
B3: Reserve Income | L3: 423.263 | M3: 445.215 | N3: 433 | O3: 558 | P3: 634.274 | Q3: 711.241
B4: Other revenue | L4: 6.767 | M4: 0.547 | N4: 2 | O4: 21 | P4: 23.804 | Q4: 28.518
B5: Revenue | C5: =SUM(C3:C4) -> 0 | D5: =SUM(D3:D4) -> 0 | E5: =SUM(E3:E4) -> 0 | F5: =SUM(F3:F4) -> 0 | G5: =SUM(G3:G4) -> 0 | K5: =SUM(K3:K4) -> 0 | L5: =SUM(L3:L4) -> 430.03 | M5: =SUM(M3:M4) -> 445.762 | N5: =SUM(N3:N4) -> 435 | O5: =SUM(O3:O4) -> 579 | P5: =SUM(P3:P4) -> 658.078 | Q5: =SUM(Q3:Q4) -> 739.759 | R5: =SUM(R3:R4) -> 0 | ... T5: =SUM(T3:T4) -> 0
B6: Rev. Exp. | F6: 2730 | G6: 3330 | R6: 755.74 | S6: 764.17
B7: Distribution and transaction cost | L7: 246.901 | M7: 257.422 | P7: 406.472 | Q7: 447.199
B8: Other cocsts | L8: 1.476 | M8: 0.281 | P8: 0.47 | Q8: 0.413
B9: COGS | C9: =SUM(C7:C8) -> 0 | D9: =SUM(D7:D8) -> 0 | E9: =SUM(E7:E8) -> 0 | F9: =SUM(F7:F8) -> 0 | G9: =SUM(G7:G8) -> 0 | K9: =SUM(K7:K8) -> 0 | L9: =SUM(L7:L8) -> 248.377 | M9: =SUM(M7:M8) -> 257.703 | N9: =SUM(N7:N8) -> 0 | O9: =SUM(O7:O8) -> 0 | P9: =SUM(P7:P8) -> 406.942 | Q9: =SUM(Q7:Q8) -> 447.612 | R9: =SUM(R7:R8) -> 0 | ... T9: =SUM(T7:T8) -> 0
B10: Compensation expense | L10: 67.604 | M10: 65.269 | P10: 503.392 | Q10: 129.295
B11: G&A | L11: 35.729 | M11: 33.337 | P11: 43.14 | Q11: 45.447
B12: D&A | L12: 12.632 | M12: 13.122 | P12: 14.209 | Q12: 23.002
B13: IT infrastructure costs | L13: 6.875 | M13: 6.865 | P13: 8.76 | Q13: 9.401
B14: Marketing expenses | L14: 5.638 | M14: 4.382 | P14: 7.91 | Q14: 5.623
B15: Digital assets gains/losses | L15: 2.929 | M15: 1.285 | P15: -0.693 | Q15: -1.671
B16: Operational Income | C16: =C5-SUM(C9:C15) -> 0 | D16: =D5-SUM(D9:D15) -> 0 | E16: =E5-SUM(E9:E15) -> 0 | F16: =F5-SUM(F9:F15) -> 0 | G16: =G5-SUM(G9:G15) -> 0 | K16: =K5-SUM(K9:K15) -> 0 | L16: =L5-SUM(L9:L15) -> 50.246 | M16: =M5-SUM(M9:M15) -> 63.799 | N16: =N5-SUM(N9:N15) -> 435 | O16: =O5-SUM(O9:O15) -> 579 | P16: =P5-SUM(P9:P15) -> -325.582 | Q16: =Q5-SUM(Q9:Q15) -> 81.05 | R16: =R5-SUM(R9:R15) -> 0 | ... T16: =T5-SUM(T9:T15) -> 0
B17: Other expense/income | L17: 1.921 | M17: 22.365 | P17: -160.421 | Q17: 72.071
B18: Net Income before Tax | C18: =C16+SUM(C17:C17) -> 0 | D18: =D16+SUM(D17:D17) -> 0 | E18: =E16+SUM(E17:E17) -> 0 | F18: =F16+SUM(F17:F17) -> 0 | G18: =G16+SUM(G17:G17) -> 0 | K18: =K16+SUM(K17:K17) -> 0 | L18: =L16+SUM(L17:L17) -> 52.167 | M18: =M16+SUM(M17:M17) -> 86.164 | N18: =N16+SUM(N17:N17) -> 435 | O18: =O16+SUM(O17:O17) -> 579 | P18: =P16+SUM(P17:P17) -> -486.003 | Q18: =Q16+SUM(Q17:Q17) -> 153.121 | R18: =R16+SUM(R17:R17) -> 0 | ... T18: =T16+SUM(T17:T17) -> 0
B19: Income Tax | L19: 19.244 | M19: 15.168 | P19: -3.903 | Q19: -61.294
B20: Net Income | C20: =C18-SUM(C19:C19) -> 0 | D20: =D18-SUM(D19:D19) -> 0 | E20: =E18-SUM(E19:E19) -> 0 | F20: =F18-SUM(F19:F19) -> 0 | G20: =G18-SUM(G19:G19) -> 0 | K20: =K18-SUM(K19:K19) -> 0 | L20: =L18-SUM(L19:L19) -> 32.923 | M20: =M18-SUM(M19:M19) -> 70.996 | N20: =N18-SUM(N19:N19) -> 435 | O20: =O18-SUM(O19:O19) -> 579 | P20: =P18-SUM(P19:P19) -> -482.1 | Q20: =Q18-SUM(Q19:Q19) -> 214.415 | R20: =R18-SUM(R19:R19) -> 0 | ... T20: =T18-SUM(T19:T19) -> 0
B21: Shares | L21: 70.416 | M21: 73.125 | P21: 107.514 | Q21: 266.682
B22: EPS | C22: =C20/C21 -> #DIV/0! | D22: =D20/D21 -> #DIV/0! | E22: =E20/E21 -> #DIV/0! | F22: =F20/F21 -> #DIV/0! | G22: =G20/G21 -> #DIV/0! | K22: =K20/K21 -> #DIV/0! | L22: =L20/L21 -> 0.46754999 | M22: =M20/M21 -> 0.97088547 | N22: =N20/N21 -> #DIV/0! | O22: =O20/O21 -> #DIV/0! | P22: =P20/P21 -> -4.4840672 | Q22: =Q20/Q21 -> 0.80401002 | R22: =R20/R21 -> #DIV/0! | ... T22: =T20/T21 -> #DIV/0!
B23: EPS exp. | F23: -1.41 | G23: 1.16 | R23: 0.19 | S23: 0.23
B24: Gross Margin | C24: =1-C9/C5 -> #DIV/0! | D24: =1-D9/D5 -> #DIV/0! | E24: =1-E9/E5 -> #DIV/0! | F24: =1-F9/F5 -> #DIV/0! | G24: =1-G9/G5 -> #DIV/0! | K24: =1-K9/K5 -> #DIV/0! | L24: =1-L9/L5 -> 0.42241937 | M24: =1-M9/M5 -> 0.42188208 | N24: =1-N9/N5 -> 1 | O24: =1-O9/O5 -> 1 | P24: =1-P9/P5 -> 0.38162042 | Q24: =1-Q9/Q5 -> 0.39492186 | R24: =1-R9/R5 -> #DIV/0! | ... T24: =1-T9/T5 -> #DIV/0!
B25: Net Margin | C25: =C20/C5 -> #DIV/0! | D25: =D20/D5 -> #DIV/0! | E25: =E20/E5 -> #DIV/0! | F25: =F20/F5 -> #DIV/0! | G25: =G20/G5 -> #DIV/0! | K25: =K20/K5 -> #DIV/0! | L25: =L20/L5 -> 0.076559775 | M25: =M20/M5 -> 0.15926885 | N25: =N20/N5 -> 1 | O25: =O20/O5 -> 1 | P25: =P20/P5 -> -0.73258793 | Q25: =Q20/Q5 -> 0.2898444 | R25: =R20/R5 -> #DIV/0! | ... T25: =T20/T5 -> #DIV/0!
B26: Revenue Growth | D26: =D5/C5-1 -> #DIV/0! | E26: =E5/D5-1 -> #DIV/0! | F26: =F5/E5-1 -> #DIV/0! | G26: =G5/F5-1 -> #DIV/0! | O26: =O5/K5-1 -> #DIV/0! | P26: =P5/L5-1 -> 0.53030719 | Q26: =Q5/M5-1 -> 0.65953805 | R26: =R5/N5-1 -> -1 | S26: =S5/O5-1 -> -1 | T26: =T5/P5-1 -> -1
B27: Compensation Expense / REV | C27: =C10/C5 -> #DIV/0! | D27: =D10/D5 -> #DIV/0! | E27: =E10/E5 -> #DIV/0! | F27: =F10/F5 -> #DIV/0! | G27: =G10/G5 -> #DIV/0! | K27: =K10/K5 -> #DIV/0! | L27: =L10/L5 -> 0.15720764 | M27: =M10/M5 -> 0.14642118 | N27: =N10/N5 -> 0 | O27: =O10/O5 -> 0 | P27: =P10/P5 -> 0.76494276 | Q27: =Q10/Q5 -> 0.17477989 | R27: =R10/R5 -> #DIV/0! | ... T27: =T10/T5 -> #DIV/0!
B28: Marketing / REV | C28: =C14/C5 -> #DIV/0! | D28: =D14/D5 -> #DIV/0! | E28: =E14/E5 -> #DIV/0! | F28: =F14/F5 -> #DIV/0! | G28: =G14/G5 -> #DIV/0! | K28: =K14/K5 -> #DIV/0! | L28: =L14/L5 -> 0.013110713 | M28: =M14/M5 -> 0.0098303579 | N28: =N14/N5 -> 0 | O28: =O14/O5 -> 0 | P28: =P14/P5 -> 0.012019852 | Q28: =Q14/Q5 -> 0.0076011241 | R28: =R11/R5 -> #DIV/0! | S28: =S11/S5 -> #DIV/0! | T28: =T11/T5 -> #DIV/0!
B29: G&A / REV | C29: =C11/C5 -> #DIV/0! | D29: =D11/D5 -> #DIV/0! | E29: =E11/E5 -> #DIV/0! | F29: =F11/F5 -> #DIV/0! | G29: =G11/G5 -> #DIV/0! | K29: =K11/K5 -> #DIV/0! | L29: =L11/L5 -> 0.083084901 | M29: =M11/M5 -> 0.074786545 | N29: =N11/N5 -> 0 | O29: =O11/O5 -> 0 | P29: =P11/P5 -> 0.065554539 | Q29: =Q11/Q5 -> 0.061434873 | R29: =R11/R5 -> #DIV/0! | ... T29: =T11/T5 -> #DIV/0!
B30: Prod1 y/y | D30: =D3/C3-1 -> #DIV/0! | E30: =E3/D3-1 -> #DIV/0! | F30: =F3/E3-1 -> #DIV/0! | G30: =G3/F3-1 -> #DIV/0!
B31: Prod2 y/y | D31: =D4/C4-1 -> #DIV/0! | E31: =E4/D4-1 -> #DIV/0! | F31: =F4/E4-1 -> #DIV/0! | G31: =G4/F4-1 -> #DIV/0!
B32: EPS Growth | C32: =C22/#REF!-1 -> #DIV/0! | D32: =D22/C22-1 -> #DIV/0! | E32: =E22/D22-1 -> #DIV/0! | F32: =F22/E22-1 -> #DIV/0! | G32: =G22/F22-1 -> #DIV/0! | O32: =O20/K20-1 -> #DIV/0! | P32: =P20/L20-1 -> -15.643259 | Q32: =Q20/M20-1 -> 2.0200997 | R32: =R20/N20-1 -> -1 | S32: =S20/O20-1 -> -1 | T32: =T20/P20-1 -> -1
B36: Net Cash | C36: =C37+C38-C58-C55 -> 0 | D36: =D37+D38-D58-D55 -> 0 | E36: =E37+E38-E58-E55 -> 1004.757 | F36: =F37+F38-F58-F55 -> 0 | G36: =G37+G38-G58-G55 -> 0 | K36: =K37+K38-K58-K55 -> 0 | L36: =L37+L38-L58-L55 -> 0 | M36: =M37+M38-M58-M55 -> 0 | N36: =N37+N38-N58-N55 -> 1004.757 | O36: =O37+O38-O58-O55 -> 0 | P36: =P37+P38-P58-P55 -> 1500.25 | Q36: =Q37+Q38-Q58-Q55 -> 2036.95 | R36: =R37+R38-R58-R55 -> 0 | ... T36: =T37+T38-T58-T55 -> 0
B37: Cash | E37: 750.981 | N37: =E37 -> 750.981 | P37: 1118.119 | Q37: 1348.901
B38: Stablecoin Cash corporate | E38: 294.493 | N38: =E38 -> 294.493 | P38: 588.271 | Q38: 837.143
B39: Stablecoin Cash | E39: 43918.572 | N39: =E39 -> 43918.572 | P39: 61365.92 | Q39: 73372.843
B40: AR | E40: 6.418 | N40: =E40 -> 6.418 | P40: 13.215 | Q40: 22.154
B41: Stablecoins receivable | E41: 6.957 | N41: =E41 -> 6.957 | Q41: 1
B42: Prepaid Expense | E42: 187.528 | N42: =E42 -> 187.528 | P42: 216.604 | Q42: 321.343
B43: Current Assets | C43: =SUM(C37:C42) -> 0 | D43: =SUM(D37:D42) -> 0 | E43: =SUM(E37:E42) -> 45164.949 | F43: =SUM(F37:F42) -> 0 | G43: =SUM(G37:G42) -> 0 | K43: =SUM(K37:K42) -> 0 | L43: =SUM(L37:L42) -> 0 | M43: =SUM(M37:M42) -> 0 | N43: =SUM(N37:N42) -> 45164.949 | O43: =SUM(O37:O42) -> 0 | P43: =SUM(P37:P42) -> 63302.129 | Q43: =SUM(Q37:Q42) -> 75903.384 | R43: =SUM(R37:R42) -> 0 | ... T43: =SUM(T37:T42) -> 0
...

Sheet Analysts
B1: 45839 | C1: 45870 | D1: 45901 | E1: 45931 | F1: 45962 | G1: 45992 | H1: 46023
A2: Sell | B2: 1 | C2: 3 | D2: 3 | E2: 4 | F2: 4 | G2: 4
A3: Hold | B3: 4 | C3: 5 | D3: 5 | E3: 8 | F3: 10 | G3: 9
A4: Buy | B4: 5 | C4: 5 | D4: 5 | E4: 4 | F4: 6 | G4: 8
A5: Strong buy | B5: 1 | C5: 1 | D5: 1 | E5: 1 | F5: 1 | G5: 2
A8: Price Targets
A9: Stock Price | B9: 199 | C9: 180 | D9: 128 | E9: 138 | F9: 116 | G9: 84.35
A10: Consensus | B10: 190 | C10: 175 | D10: 171 | E10: 171 | F10: 165 | G10: 145

Sheet Model-graph
A1: Main

Sheet KPIs
B1: Q324 | C1: Q424 | D1: Q125 | E1: Q225 | F1: Q325
A2: Market
A3: Stablecoins in Circulation | B3: 160 | C3: 185 | D3: 208 | E3: 223 | F3: 254
A4: Stablecoin Transaction Volumes | B4: 1.3 | C4: 1.9 | D4: 2 | E4: 2.2 | F4: 2.9
A7: USD in Circulation in b | F7: 73.7
A8: Reserve Return Rate | F8: 0.042
A9: Stablecoin Marketshare | B9: 0.23 | C9: 0.24 | D9: 0.29 | E9: 0.28 | F9: 0.29
A10: Transaction Marketshare | B10: 0.3 | C10: 0.33 | D10: 0.39 | E10: 0.36 | F10: 0.4

Sheet Catalysts
A1: Main | B1: Date | C1: Close
E2: Date | F2: Event | M2: Earnings
E3: 45328 | F3: xxx
E4: 45302 | F4: xxx

Sheet DoR
A1: Main | B1: Date | C1: Price | D1: w/w | H1: Close to Close Weekly returns
D2: =C2/C3-1 -> #DIV/0!
D3: =C3/C4-1 -> #DIV/0! | H3: Intervals | I3: Bin | J3: Frequency | K3: Range | L3: Probability | M3: Cumulative Percentage
D4: =C4/C5-1 -> #DIV/0! | H4: =$I$19-3*$I$23 -> #DIV/0! | I4: =H4 -> #DIV/0! | J4: =COUNTIF(D:D,"<="&H4) -> 67 | K4: ="Less than "&TEXT(H4,"0,00%") -> #DIV/0! | L4: =J4/$I$31 -> #DIV/0! | M4: =L4 -> #DIV/0!
D5: =C5/C6-1 -> #DIV/0! | H5: =$I$19-2.4*$I$23 -> #DIV/0! | I5: =H5 -> #DIV/0! | J5: =COUNTIFS(D:D,"<="&H5,D:D,">"&H4) -> 67 | K5: =TEXT(H4,"0,00%")&" to "&TEXT(H5,"0,00%") -> #DIV/0! | L5: =J5/$I$31 -> #DIV/0! | M5: =M4+L5 -> #DIV/0!
D6: =C6/C7-1 -> #DIV/0! | H6: =$I$19-1.8*$I$23 -> #DIV/0! | I6: =H6 -> #DIV/0! | J6: =COUNTIFS(D:D,"<="&H6,D:D,">"&H5) -> 67 | K6: =TEXT(H5,"0,00%")&" to "&TEXT(H6,"0,00%") -> #DIV/0! | L6: =J6/$I$31 -> #DIV/0! | M6: =M5+L6 -> #DIV/0!
D7: =C7/C8-1 -> #DIV/0! | H7: =$I$19-1.2*$I$23 -> #DIV/0! | I7: =H7 -> #DIV/0! | J7: =COUNTIFS(D:D,"<="&H7,D:D,">"&H6) -> 67 | K7: =TEXT(H6,"0,00%")&" to "&TEXT(H7,"0,00%") -> #DIV/0! | L7: =J7/$I$31 -> #DIV/0! | M7: =M6+L7 -> #DIV/0!
D8: =C8/C9-1 -> #DIV/0! | H8: =$I$19-0.6*$I$23 -> #DIV/0! | I8: =H8 -> #DIV/0! | J8: =COUNTIFS(D:D,"<="&H8,D:D,">"&H7) -> 67 | K8: =TEXT(H7,"0,00%")&" to "&TEXT(H8,"0,00%") -> #DIV/0! | L8: =J8/$I$31 -> #DIV/0! | M8: =M7+L8 -> #DIV/0!
D9: =C9/C10-1 -> #DIV/0! | H9: =$I$19 -> #DIV/0! | I9: =H9 -> #DIV/0! | J9: =COUNTIFS(D:D,"<="&H9,D:D,">"&H8) -> 67 | K9: =TEXT(H8,"0,00%")&" to "&TEXT(H9,"0,00%") -> #DIV/0! | L9: =J9/$I$31 -> #DIV/0! | M9: =M8+L9 -> #DIV/0!
D10: =C10/C11-1 -> #DIV/0! | H10: =$I$19+0.6*$I$23 -> #DIV/0! | I10: =H10 -> #DIV/0! | J10: =COUNTIFS(D:D,"<="&H10,D:D,">"&H9) -> 67 | K10: =TEXT(H9,"0,00%")&" to "&TEXT(H10,"0,00%") -> #DIV/0! | L10: =J10/$I$31 -> #DIV/0! | M10: =M9+L10 -> #DIV/0!
D11: =C11/C12-1 -> #DIV/0! | H11: =$I$19+1.2*$I$23 -> #DIV/0! | I11: =H11 -> #DIV/0! | J11: =COUNTIFS(D:D,"<="&H11,D:D,">"&H10) -> 67 | K11: =TEXT(H10,"0,00%")&" to "&TEXT(H11,"0,00%") -> #DIV/0! | L11: =J11/$I$31 -> #DIV/0! | M11: =M10+L11 -> #DIV/0!
D12: =C12/C13-1 -> #DIV/0! | H12: =$I$19+1.8*$I$23 -> #DIV/0! | I12: =H12 -> #DIV/0! | J12: =COUNTIFS(D:D,"<="&H12,D:D,">"&H11) -> 67 | K12: =TEXT(H11,"0,00%")&" to "&TEXT(H12,"0,00%") -> #DIV/0! | L12: =J12/$I$31 -> #DIV/0! | M12: =M11+L12 -> #DIV/0!
D13: =C13/C14-1 -> #DIV/0! | H13: =$I$19+2.4*$I$23 -> #DIV/0! | I13: =H13 -> #DIV/0! | J13: =COUNTIFS(D:D,"<="&H13,D:D,">"&H12) -> 67 | K13: =TEXT(H12,"0,00%")&" to "&TEXT(H13,"0,00%") -> #DIV/0! | L13: =J13/$I$31 -> #DIV/0! | M13: =M12+L13 -> #DIV/0!
D14: =C14/C15-1 -> #DIV/0! | H14: =$I$19+3*$I$23 -> #DIV/0! | I14: =H14 -> #DIV/0! | J14: =COUNTIFS(D:D,"<="&H14,D:D,">"&H13) -> 67 | K14: =TEXT(H13,"0,00%")&" to "&TEXT(H14,"0,00%") -> #DIV/0! | L14: =J14/$I$31 -> #DIV/0! | M14: =M13+L14 -> #DIV/0!
D15: =C15/C16-1 -> #DIV/0! | I15: More | J15: =COUNTIF(D:D,">"&H14) -> 67 | K15: ="Greater than "&TEXT(H14,"0,00%") -> #DIV/0! | L15: =J15/$I$31 -> #DIV/0! | M15: =M14+L15 -> #DIV/0!
D16: =C16/C17-1 -> #DIV/0!
D17: =C17/C18-1 -> #DIV/0! | H17: Descriptive Statistics
D18: =C18/C19-1 -> #DIV/0!
D19: =C19/C20-1 -> #DIV/0! | H19: Mean | I19: =AVERAGE(D:D) -> #DIV/0!
D20: =C20/C21-1 -> #DIV/0! | H20: Standard Error | I20: =_xlfn.STDEV.S(D:D)/SQRT(COUNT(D:D)) -> #DIV/0!
D21: =C21/C22-1 -> #DIV/0! | H21: Median | I21: =MEDIAN(D:D) -> #DIV/0!
D22: =C22/C23-1 -> #DIV/0! | H22: Mode | I22: =MODE(D:D) -> #DIV/0!
D23: =C23/C24-1 -> #DIV/0! | H23: Standard Deviation | I23: =_xlfn.STDEV.S(D:D) -> #DIV/0!
D24: =C24/C25-1 -> #DIV/0! | H24: Sample Variance | I24: =_xlfn.VAR.S(D:D) -> #DIV/0!
D25: =C25/C26-1 -> #DIV/0! | H25: Kurtosis | I25: =KURT(D:D) -> #DIV/0!
D26: =C26/C27-1 -> #DIV/0! | H26: Skewness | I26: =SKEW(D:D) -> #DIV/0!
D27: =C27/C28-1 -> #DIV/0! | H27: Range | I27: =I29-I28 -> #DIV/0!
D28: =C28/C29-1 -> #DIV/0! | H28: Minimum | I28: =MIN(D:D) -> #DIV/0!
D29: =C29/C30-1 -> #DIV/0! | H29: Maximum | I29: =MAX(D:D) -> #DIV/0!
D30: =C30/C31-1 -> #DIV/0! | H30: Sum | I30: =SUM(D:D) -> #DIV/0!
D31: =C31/C32-1 -> #DIV/0! | H31: Count | I31: =COUNT(D:D) -> 0
D32: =C32/C33-1 -> #DIV/0!
D33: =C33/C34-1 -> #DIV/0! | I33: Average Returns | J33: Count | K33: Frequency % | L33: Frequency Adjusted Return
D34: =C34/C35-1 -> #DIV/0! | H34: Positive Data Points | I34: =AVERAGEIF(D:D,">0") -> #DIV/0! | J34: =COUNTIF(D:D,">0") -> 0 | K34: =J34/$I$31 -> #DIV/0! | L34: =K34*I34 -> #DIV/0!
D35: =C35/C36-1 -> #DIV/0! | H35: Negative Data Points | I35: =AVERAGEIF(D:D,"<0") -> #DIV/0! | J35: =COUNTIF(D:D,"<0") -> 0 | K35: =J35/$I$31 -> #DIV/0! | L35: =K35*I35 -> #DIV/0!
D36: =C36/C37-1 -> #DIV/0! | H36: Zero | I36: 0 | J36: =COUNTIF(D:D,"0") -> 0 | K36: =J36/$I$31 -> #DIV/0! | L36: =K36*I36 -> #DIV/0!
D37: =C37/C38-1 -> #DIV/0!
D38: =C38/C39-1 -> #DIV/0! | H38: Std Dev | I38: Upper Bound | J38: Lower Bound | K38: Actual Count | L38: Actual % Count | M38: Normal % Count
D39: =C39/C40-1 -> #DIV/0! | H39: 1 | I39: =$I$19+($H39*$I$23) -> #DIV/0! | J39: =$I$19-($H39*$I$23) -> #DIV/0! | K39: =COUNTIFS(D:D,"<"&I39,D:D,">"&J39) -> 67 | L39: =K39/$I$31 -> #DIV/0! | M39: 0.6827
D40: =C40/C41-1 -> #DIV/0! | H40: 2 | I40: =$I$19+($H40*$I$23) -> #DIV/0! | J40: =$I$19-($H40*$I$23) -> #DIV/0! | K40: =COUNTIFS(D:D,"<"&I40,D:D,">"&J40) -> 67 | L40: =K40/$I$31 -> #DIV/0! | M40: 0.9545
...
